Workbook
Name cad_Fontes: Cadastros!$E$2:$E$4
Name cad_Inst: Cadastros!$A$2:$A$200
Name cad_Meses: Cadastros!$G$2:$G$500
Name cad_Mod: Cadastros!$C$2:$C$200
Name col_Ap: Base!$P$2:$P$50000
Name col_Data: Base!$A$2:$A$50000
Name col_Fonte: Base!$C$2:$C$50000
Name col_ID: Base!$B$2:$B$50000
Name col_Inst: Base!$E$2:$E$50000
Name col_IOFR: Base!$V$2:$V$50000
Name col_IRP: Base!$W$2:$W$50000
Name col_IRR: Base!$U$2:$U$50000
Name col_Jur: Base!$R$2:$R$50000
Name col_Mod: Base!$F$2:$F$50000
Name col_Mov: Base!$BA$2:$BA$50000
Name col_Rend: Base!$S$2:$S$50000
Name col_Res: Base!$Q$2:$Q$50000
Name col_SA: Base!$O$2:$O$50000
Name col_SF: Base!$T$2:$T$50000
Name col_SMed: Base!$BB$2:$BB$50000
Name ind_CDI: Indicadores!$B$2:$B$500
Name ind_IPCA: Indicadores!$C$2:$C$500
Name ind_Mes: Indicadores!$A$2:$A$500
Name ind_Orig: Indicadores!$D$2:$D$500
Name LimiteConc: Config!$B$4
Name MesAnt: Config!$B$9
Name MesRef: Config!$B$3
Name MetaCDI: Config!$B$5
Name PastaPDF: Config!$B$7
Name QtdAlertas: Conferencias!$C$4
Name QtdErros: Conferencias!$C$3
Name StatusRelatorio: Config!$B$8
Name TolContinuidade: Config!$B$6

Sheet LEIAME
A1: Gerador de Relatório Executivo de Carteira de Renda Fixa — ARQUIVO DE EXEMPLO
A2: Todos os dados deste arquivo são FICTÍCIOS e servem apenas para demonstração.
A4: Como usar:
A5: 1. Salve este arquivo como 'Pasta de Trabalho Habilitada para Macro (*.xlsm)'.
A6: 2. Abra o editor VBA (Alt+F11), selecione ESTE arquivo no painel e importe os 3 módulos da pasta /vba.
A7: 3. Execute a macro CriarBotoes (Alt+F8) uma única vez para criar os botões na aba Resumo.
A8: 4. Clique em 'Importar mês' e escolha exemplos/planilha_mensal_2025-04_data_fim_de_semana.xlsx.
A9: 5. Veja a aba Conferencias: deve aparecer ALERTA de data-base em fim de semana (não bloqueia o PDF).
A10: 6. Importe exemplos/planilha_mensal_2025-05_com_erro.xlsx: deve aparecer ERRO (instituição não cadastrada).
A11: 7. Clique em 'Gerar PDF'. Com ERRO, a macro só permite gerar a versão PRELIMINAR.
A13: Células com fundo amarelo e fonte azul são entradas manuais. As demais são fórmulas: não sobrescreva.
A14: A macro NÃO salva a base automaticamente: revise e salve manualmente após cada importação.

Sheet Resumo
A1: Relatório Executivo de Investimentos
A2: ="Mês de referência: "&CHOOSE(MONTH(MesRef),"janeiro","fevereiro","março","abril","maio","junho","julho","agosto","setembro","outubro","novembro","dezembro")&"/"&YEAR(MesRef)&" | Dados fictícios de demonstração" -> Mês de referência: março/2025 | Dados fictícios de demonstração
A3: =IF(StatusRelatorio="PRELIMINAR","VERSÃO PRELIMINAR — há conferências com ERRO","")
A5: 1. Resultado do mês
A6: Indicador | B6: Mês de referência | C6: Mês anterior | D6: Variação
A7: Saldo final total | B7: =SUMIFS(col_SF,col_Data,MesRef) -> 42617210 | C7: =SUMIFS(col_SF,col_Data,MesAnt) -> 43347596 | D7: =B7-C7 -> -730386.18
A8: Aplicações | B8: =SUMIFS(col_Ap,col_Data,MesRef) -> 23401.98 | C8: =SUMIFS(col_Ap,col_Data,MesAnt) -> 610878.52 | D8: =B8-C8 -> -587476.54
A9: Resgates | B9: =SUMIFS(col_Res,col_Data,MesRef) -> 1102210.5 | C9: =SUMIFS(col_Res,col_Data,MesAnt) -> 742352.27 | D9: =B9-C9 -> 359858.26
A10: Juros recebidos | B10: =SUMIFS(col_Jur,col_Data,MesRef) -> 0 | C10: =SUMIFS(col_Jur,col_Data,MesAnt) -> 0 | D10: =B10-C10 -> 0
A11: Rendimento bruto | B11: =SUMIFS(col_Rend,col_Data,MesRef) -> 359745.59 | C11: =SUMIFS(col_Rend,col_Data,MesAnt) -> 341221.07 | D11: =B11-C11 -> 18524.52
A12: IR/IOF retido na cota | B12: =SUMIFS(col_IRR,col_Data,MesRef)+SUMIFS(col_IOFR,col_Data,MesRef) -> 11323.22 | C12: =SUMIFS(col_IRR,col_Data,MesAnt)+SUMIFS(col_IOFR,col_Data,MesAnt) -> 10149.92 | D12: =B12-C12 -> 1173.3
A13: IR provisionado | B13: =SUMIFS(col_IRP,col_Data,MesRef) -> 28174.91 | C13: =SUMIFS(col_IRP,col_Data,MesAnt) -> 27916.47 | D13: =B13-C13 -> 258.44
A14: Saldo médio (média simples) | B14: =SUMIFS(col_SMed,col_Data,MesRef) -> 42982403 | C14: =SUMIFS(col_SMed,col_Data,MesAnt) -> 43247798 | D14: =B14-C14 -> -265394.39
A15: Rentabilidade do mês | B15: =IFERROR(B11/B14,0) -> 0.0083696016 | C15: =IFERROR(C11/C14,0) -> 0.0078899063 | D15: =B15-C15 -> 0.0004796953
A16: CDI do mês | B16: =IFERROR(INDEX(ind_CDI,MATCH(MesRef,ind_Mes,0)),0) -> 0.0097 | C16: =IFERROR(INDEX(ind_CDI,MATCH(MesAnt,ind_Mes,0)),0) -> 0.0088 | D16: =B16-C16 -> 0.0009
A17: Rentabilidade em % do CDI | B17: =IFERROR(B15/B16,0) -> 0.86284552 | C17: =IFERROR(C15/C16,0) -> 0.89658026 | D17: =B17-C17 -> -0.033734735
A18: Meta (% do CDI) | B18: =MetaCDI -> 1 | C18: =MetaCDI -> 1 | D18: =B18-C18 -> 0
A19: Situação da meta | B19: =IF(B17>=B18,"Atingida","Não atingida") -> Não atingida | C19: =IF(C16=0,"-",IF(C17>=C18,"Atingida","Não atingida")) -> Não atingida
A21: 2. Variação do rendimento: efeito volume × efeito taxa
A22: Variação do rendimento bruto | B22: =B11-C11 -> 18524.52
A23: Efeito volume = (saldo médio atual − anterior) × taxa anterior | B23: =IFERROR((B14-C14)*C15,0) -> -2093.9369
A24: Efeito taxa = variação − efeito volume | B24: =B22-B23 -> 20618.457
A26: 3. Distribuição por fonte de recursos
A27: Fonte | B27: Saldo final | C27: Participação | D27: Rendimento bruto
A28: =Cadastros!E2 -> Recursos Proprios | B28: =SUMIFS(col_SF,col_Data,MesRef,col_Fonte,A28) -> 21296607 | C28: =IFERROR(B28/$B$7,0) -> 0.49971846 | D28: =SUMIFS(col_Rend,col_Data,MesRef,col_Fonte,A28) -> 190325.32
A29: =Cadastros!E3 -> Recursos de Terceiros | B29: =SUMIFS(col_SF,col_Data,MesRef,col_Fonte,A29) -> 9993010.5 | C29: =IFERROR(B29/$B$7,0) -> 0.23448298 | D29: =SUMIFS(col_Rend,col_Data,MesRef,col_Fonte,A29) -> 76122.12
A30: =Cadastros!E4 -> Financiamento de Base | B30: =SUMIFS(col_SF,col_Data,MesRef,col_Fonte,A30) -> 11327593 | C30: =IFERROR(B30/$B$7,0) -> 0.26579856 | D30: =SUMIFS(col_Rend,col_Data,MesRef,col_Fonte,A30) -> 93298.15
A31: Total | B31: =SUM(B28:B30) -> 42617210 | C31: =SUM(C28:C30) -> 1 | D31: =SUM(D28:D30) -> 359745.59
A33: 4. Concentração por instituição
A34: Instituição | B34: Saldo final | C34: Participação | D34: Limite | E34: Margem | F34: Situação
A35: =IF(Cadastros!A2="","",Cadastros!A2) -> Banco Alfa | B35: =IF(A35="","",SUMIFS(col_SF,col_Data,MesRef,col_Inst,A35)) -> 14664011 | C35: =IF(A35="","",IFERROR(B35/$B$7,0)) -> 0.3440866 | D35: =IF(A35="","",LimiteConc) -> 0.3 | E35: =IF(A35="","",D35-C35) -> -0.044086597 | F35: =IF(A35="","",IF(C35>D35,"Atenção","Conforme")) -> Atenção
A36: =IF(Cadastros!A3="","",Cadastros!A3) -> Banco Beta | B36: =IF(A36="","",SUMIFS(col_SF,col_Data,MesRef,col_Inst,A36)) -> 9329108.5 | C36: =IF(A36="","",IFERROR(B36/$B$7,0)) -> 0.21890472 | D36: =IF(A36="","",LimiteConc) -> 0.3 | E36: =IF(A36="","",D36-C36) -> 0.08109528 | F36: =IF(A36="","",IF(C36>D36,"Atenção","Conforme")) -> Conforme
A37: =IF(Cadastros!A4="","",Cadastros!A4) -> Banco Gama | B37: =IF(A37="","",SUMIFS(col_SF,col_Data,MesRef,col_Inst,A37)) -> 3020589.4 | C37: =IF(A37="","",IFERROR(B37/$B$7,0)) -> 0.070877221 | D37: =IF(A37="","",LimiteConc) -> 0.3 | E37: =IF(A37="","",D37-C37) -> 0.22912278 | F37: =IF(A37="","",IF(C37>D37,"Atenção","Conforme")) -> Conforme
A38: =IF(Cadastros!A5="","",Cadastros!A5) -> Cooperativa Delta | B38: =IF(A38="","",SUMIFS(col_SF,col_Data,MesRef,col_Inst,A38)) -> 6320893.6 | C38: =IF(A38="","",IFERROR(B38/$B$7,0)) -> 0.14831786 | D38: =IF(A38="","",LimiteConc) -> 0.3 | E38: =IF(A38="","",D38-C38) -> 0.15168214 | F38: =IF(A38="","",IF(C38>D38,"Atenção","Conforme")) -> Conforme
A39: =IF(Cadastros!A6="","",Cadastros!A6) -> Banco Epsilon | B39: =IF(A39="","",SUMIFS(col_SF,col_Data,MesRef,col_Inst,A39)) -> 9282607.9 | C39: =IF(A39="","",IFERROR(B39/$B$7,0)) -> 0.2178136 | D39: =IF(A39="","",LimiteConc) -> 0.3 | E39: =IF(A39="","",D39-C39) -> 0.082186402 | F39: =IF(A39="","",IF(C39>D39,"Atenção","Conforme")) -> Conforme
A40: =IF(Cadastros!A7="","",Cadastros!A7) | B40: =IF(A40="","",SUMIFS(col_SF,col_Data,MesRef,col_Inst,A40)) | C40: =IF(A40="","",IFERROR(B40/$B$7,0)) | D40: =IF(A40="","",LimiteConc) | E40: =IF(A40="","",D40-C40) | F40: =IF(A40="","",IF(C40>D40,"Atenção","Conforme"))
A41: =IF(Cadastros!A8="","",Cadastros!A8) | B41: =IF(A41="","",SUMIFS(col_SF,col_Data,MesRef,col_Inst,A41)) | C41: =IF(A41="","",IFERROR(B41/$B$7,0)) | D41: =IF(A41="","",LimiteConc) | E41: =IF(A41="","",D41-C41) | F41: =IF(A41="","",IF(C41>D41,"Atenção","Conforme"))
A42: =IF(Cadastros!A9="","",Cadastros!A9) | B42: =IF(A42="","",SUMIFS(col_SF,col_Data,MesRef,col_Inst,A42)) | C42: =IF(A42="","",IFERROR(B42/$B$7,0)) | D42: =IF(A42="","",LimiteConc) | E42: =IF(A42="","",D42-C42) | F42: =IF(A42="","",IF(C42>D42,"Atenção","Conforme"))
A43: =IF(Cadastros!A10="","",Cadastros!A10) | B43: =IF(A43="","",SUMIFS(col_SF,col_Data,MesRef,col_Inst,A43)) | C43: =IF(A43="","",IFERROR(B43/$B$7,0)) | D43: =IF(A43="","",LimiteConc) | E43: =IF(A43="","",D43-C43) | F43: =IF(A43="","",IF(C43>D43,"Atenção","Conforme"))
A44: =IF(Cadastros!A11="","",Cadastros!A11) | B44: =IF(A44="","",SUMIFS(col_SF,col_Data,MesRef,col_Inst,A44)) | C44: =IF(A44="","",IFERROR(B44/$B$7,0)) | D44: =IF(A44="","",LimiteConc) | E44: =IF(A44="","",D44-C44) | F44: =IF(A44="","",IF(C44>D44,"Atenção","Conforme"))
...

Sheet Conferencias
A1: Conferências de qualidade dos dados
B3: Quantidade de ERROS (bloqueiam o PDF final) | C3: =COUNTIF(E8:E30,"ERRO") -> 0
B4: Quantidade de ALERTAS (não bloqueiam) | C4: =COUNTIF(E8:E30,"ALERTA") -> 0
A7: # | B7: Conferência | C7: Resultado | D7: Critério | E7: Status
A8: 1 | B8: Mês de referência cadastrado | C8: =COUNTIF(cad_Meses,MesRef) -> 1 | D8: Deve ser ≥ 1 | E8: =IF(C8>=1,"OK","ERRO") -> OK
A9: 2 | B9: Linhas do mês na base | C9: =COUNTIF(col_Data,MesRef) -> 28 | D9: Deve ser > 0 | E9: =IF(C9>0,"OK","ERRO") -> OK
A10: 3 | B10: Linhas sem instituição ou modalidade | C10: =SUMPRODUCT((col_Data=MesRef)*(col_Inst=""))+SUMPRODUCT((col_Data=MesRef)*(col_Mod="")) -> 0 | D10: Deve ser 0 | E10: =IF(C10=0,"OK","ERRO") -> OK
A11: 4 | B11: Soma por fonte × total (diferença R$) | C11: =ROUND(SUMIFS(col_SF,col_Data,MesRef)-SUMPRODUCT(SUMIFS(col_SF,col_Data,MesRef,col_Fonte,cad_Fontes)),2) -> 0 | D11: Deve ser 0,00 | E11: =IF(ABS(C11)<0.01,"OK","ERRO") -> OK
A12: 5 | B12: Instituições não cadastradas (linhas) | C12: =SUMPRODUCT((col_Data=MesRef)*(COUNTIF(cad_Inst,col_Inst)=0)) -> 0 | D12: Deve ser 0 | E12: =IF(C12=0,"OK","ERRO") -> OK
A13: 6 | B13: Modalidades não cadastradas (linhas) | C13: =SUMPRODUCT((col_Data=MesRef)*(COUNTIF(cad_Mod,col_Mod)=0)) -> 0 | D13: Deve ser 0 | E13: =IF(C13=0,"OK","ERRO") -> OK
A14: 7 | B14: Linhas com movimentação que não fecha | C14: =SUMPRODUCT((col_Data=MesRef)*(ABS(col_Mov)>0.01)) -> 0 | D14: Deve ser 0 (tolerância R$ 0,01) | E14: =IF(C14=0,"OK","ERRO") -> OK
A15: 8 | B15: Continuidade do saldo (diferença R$) | C15: =IF(COUNTIF(col_Data,MesAnt)=0,"sem mês ant.",ROUND(SUMIFS(col_SA,col_Data,MesRef)-SUMIFS(col_SF,col_Data,MesAnt),2)) -> 0 | D15: Até a tolerância da aba Config | E15: =IF(ISNUMBER(C15),IF(ABS(C15)<=TolContinuidade,"OK","ALERTA"),"ALERTA") -> OK
A16: 9 | B16: Data-base original em dia útil | C16: =IFERROR(INDEX(ind_Orig,MATCH(MesRef,ind_Mes,0)),"não localizada") -> 45747 | D16: Segunda a sexta (feriados não considerados) | E16: =IF(ISNUMBER(C16),IF(WEEKDAY(C16,2)<=5,"OK","ALERTA"),"ALERTA") -> OK
A17: 10 | B17: Aplicações com rendimento negativo | C17: =SUMPRODUCT((col_Data=MesRef)*(col_Rend<0)) -> 0 | D17: Esperado 0 | E17: =IF(C17=0,"OK","ALERTA") -> OK
A18: 11 | B18: Mês anterior disponível na base | C18: =COUNTIF(col_Data,MesAnt) -> 28 | D18: Deve ser > 0 | E18: =IF(C18>0,"OK","ALERTA") -> OK
A19: 12 | B19: CDI do mês disponível | C19: =IFERROR(INDEX(ind_CDI,MATCH(MesRef,ind_Mes,0)),"não localizado") -> 0.0097 | D19: Deve estar preenchido | E19: =IF(AND(ISNUMBER(C19),C19<>0),"OK","ERRO") -> OK

Sheet Base
A1: Data_Base | B1: ID_Aplicacao | C1: Fonte | D1: Centro_Custo | E1: Instituicao | F1: Modalidade | G1: Produto | H1: Indexador | I1: Perc_CDI_Contratado | J1: Taxa_Prefixada | K1: Data_Aplicacao | L1: Data_Vencimento | M1: Liquidez | N1: Classificacao | O1: Saldo_Anterior | P1: Aplicacoes | Q1: Resgates | R1: Juros_Recebidos | S1: Rendimento_Bruto | T1: Saldo_Final | U1: IR_Retido | V1: IOF_Retido | W1: IR_Provisionado | X1: IOF_Provisionado | Y1: Saldo_Liquido | Z1: Rentab_Mes | AA1: Rentab_Perc_CDI | AB1: Rentab_Ano | AC1: Rentab_12m | AD1: CDI_Mes | AE1: CDI_Ano | AF1: CDI_12m | AG1: IPCA_Mes | AH1: Dias_Uteis_Mes | AI1: Prazo_Dias | AJ1: Faixa_Vencimento | AK1: Saldo_Liquido_de_IR | AL1: Aliquota_IR | AM1: Isento_IR | AN1: Garantia_FGC | AO1: Rating_Emissor | AP1: Emissor | AQ1: Custodiante | AR1: Conta_Referencia | AS1: Tipo_Resgate | AT1: Carencia_Dias | AU1: Enquadramento | AV1: Observacao | AW1: Area_Responsavel | AX1: Data_Atualizacao | AY1: Status | AZ1: Chave_Unica | BA1: Mov_Diferenca | BB1: Saldo_Medio
A2: 45688 | B2: APL-001 | C2: Financiamento de Base | D2: CC-002 | E2: Banco Alfa | F2: LCA | G2: LCA Banco Alfa | H2: CDI | I2: 0.9274 | K2: 45635 | L2: 46117 | M2: No vencimento | N2: Longo prazo | O2: 2235839.9 | P2: 0 | Q2: 0 | R2: 0 | S2: 19698.42 | T2: 2255538.4 | U2: 0 | V2: 0 | W2: 0 | X2: 0 | Y2: 2255538.4 | Z2: 0.00881 | AA2: 0.9274 | AD2: 0.0095 | AG2: 0.003 | AH2: 22 | AI2: 429 | AJ2: Acima de 360 dias | AK2: N | AL2: 0 | AM2: S | AN2: S | AO2: AAA | AP2: Banco Alfa | AQ2: Custodiante Ficticio | AR2: CT-001 | AS2: No vencimento | AT2: 0 | AU2: Autorizado | AW2: Financeiro | AX2: 45688 | AY2: Ativa | AZ2: APL-001-202501 | BA2: =ROUND(T2-(O2+P2-Q2-R2+S2-IF(AK2="S",U2+V2,0)),2) -> 0 | BB2: =(O2+T2)/2 -> 2245689.1
A3: 45688 | B3: APL-002 | C3: Recursos Proprios | D3: CC-009 | E3: Banco Epsilon | F3: LCA | G3: LCA Banco Epsilon | H3: CDI | I3: 0.9221 | K3: 45475 | L3: 45695 | M3: No vencimento | N3: Curto prazo | O3: 1425050.4 | P3: 0 | Q3: 0 | R3: 0 | S3: 12483.37 | T3: 1437533.8 | U3: 0 | V3: 0 | W3: 0 | X3: 0 | Y3: 1437533.8 | Z3: 0.00876 | AA3: 0.9221 | AD3: 0.0095 | AG3: 0.003 | AH3: 22 | AI3: 7 | AJ3: Ate 90 dias | AK3: N | AL3: 0 | AM3: S | AN3: S | AO3: AA | AP3: Banco Epsilon | AQ3: Custodiante Ficticio | AR3: CT-002 | AS3: No vencimento | AT3: 0 | AU3: Autorizado | AW3: Financeiro | AX3: 45688 | AY3: Ativa | AZ3: APL-002-202501 | BA3: =ROUND(T3-(O3+P3-Q3-R3+S3-IF(AK3="S",U3+V3,0)),2) -> 0 | BB3: =(O3+T3)/2 -> 1431292.1
A4: 45688 | B4: APL-003 | C4: Recursos Proprios | D4: CC-007 | E4: Banco Beta | F4: Tesouro IPCA+ | G4: Tesouro IPCA+ Banco Beta | H4: IPCA | J4: 0.0048 | K4: 45523 | L4: 46412 | M4: No vencimento | N4: Longo prazo | O4: 430924.77 | P4: 0 | Q4: 195947.52 | R4: 8618.5 | S4: 2597.02 | T4: 228955.77 | U4: 0 | V4: 0 | W4: 389.55 | X4: 0 | Y4: 228566.22 | Z4: 0.006027 | AA4: 0.6344 | AD4: 0.0095 | AG4: 0.003 | AH4: 22 | AI4: 724 | AJ4: Acima de 360 dias | AK4: N | AL4: 0.15 | AM4: N | AN4: N | AO4: AA | AP4: Banco Beta | AQ4: Custodiante Ficticio | AR4: CT-003 | AS4: No vencimento | AT4: 0 | AU4: Autorizado | AW4: Financeiro | AX4: 45688 | AY4: Ativa | AZ4: APL-003-202501 | BA4: =ROUND(T4-(O4+P4-Q4-R4+S4-IF(AK4="S",U4+V4,0)),2) -> 0 | BB4: =(O4+T4)/2 -> 329940.27
A5: 45688 | B5: APL-004 | C5: Recursos de Terceiros | D5: CC-005 | E5: Banco Alfa | F5: Tesouro Selic | G5: Tesouro Selic Banco Alfa | H5: CDI | I5: 1.0061 | K5: 45335 | L5: 45836 | M5: No vencimento | N5: Curto prazo | O5: 1837842.9 | P5: 0 | Q5: 0 | R5: 0 | S5: 17566.01 | T5: 1855408.9 | U5: 0 | V5: 0 | W5: 2634.9 | X5: 0 | Y5: 1852774 | Z5: 0.009558 | AA5: 1.0061 | AD5: 0.0095 | AG5: 0.003 | AH5: 22 | AI5: 148 | AJ5: 91 a 360 dias | AK5: N | AL5: 0.15 | AM5: N | AN5: N | AO5: AAA | AP5: Banco Alfa | AQ5: Custodiante Ficticio | AR5: CT-004 | AS5: No vencimento | AT5: 0 | AU5: Autorizado | AW5: Financeiro | AX5: 45688 | AY5: Ativa | AZ5: APL-004-202501 | BA5: =ROUND(T5-(O5+P5-Q5-R5+S5-IF(AK5="S",U5+V5,0)),2) -> 0 | BB5: =(O5+T5)/2 -> 1846625.9
A6: 45688 | B6: APL-005 | C6: Recursos de Terceiros | D6: CC-004 | E6: Cooperativa Delta | F6: LCA | G6: LCA Cooperativa Delta | H6: CDI | I6: 0.9293 | K6: 45340 | L6: 46711 | M6: No vencimento | N6: Longo prazo | O6: 162269.74 | P6: 0 | Q6: 36504.74 | R6: 0 | S6: 1271.44 | T6: 127036.44 | U6: 0 | V6: 0 | W6: 0 | X6: 0 | Y6: 127036.44 | Z6: 0.007835 | AA6: 0.8248 | AD6: 0.0095 | AG6: 0.003 | AH6: 22 | AI6: 1023 | AJ6: Acima de 360 dias | AK6: N | AL6: 0 | AM6: S | AN6: S | AO6: AAA | AP6: Cooperativa Delta | AQ6: Custodiante Ficticio | AR6: CT-005 | AS6: No vencimento | AT6: 0 | AU6: Autorizado | AW6: Financeiro | AX6: 45688 | AY6: Ativa | AZ6: APL-005-202501 | BA6: =ROUND(T6-(O6+P6-Q6-R6+S6-IF(AK6="S",U6+V6,0)),2) -> 0 | BB6: =(O6+T6)/2 -> 144653.09
A7: 45688 | B7: APL-006 | C7: Recursos Proprios | D7: CC-002 | E7: Banco Gama | F7: Fundo DI | G7: Fundo DI Banco Gama | H7: CDI | I7: 0.959 | K7: 45350 | M7: Diaria | N7: Curto prazo | O7: 1160855.2 | P7: 0 | Q7: 0 | R7: 0 | S7: 10575.97 | T7: 1169844.8 | U7: 1586.4 | V7: 0 | W7: 0 | X7: 0 | Y7: 1169844.8 | Z7: 0.00911 | AA7: 0.959 | AD7: 0.0095 | AG7: 0.003 | AH7: 22 | AJ7: Liquidez diaria | AK7: S | AL7: 0.15 | AM7: N | AN7: N | AO7: AA | AP7: Banco Gama | AQ7: Custodiante Ficticio | AR7: CT-006 | AS7: D+0 | AT7: 0 | AU7: Autorizado | AW7: Financeiro | AX7: 45688 | AY7: Ativa | AZ7: APL-006-202501 | BA7: =ROUND(T7-(O7+P7-Q7-R7+S7-IF(AK7="S",U7+V7,0)),2) -> 0 | BB7: =(O7+T7)/2 -> 1165350
A8: 45688 | B8: APL-007 | C8: Financiamento de Base | D8: CC-002 | E8: Banco Beta | F8: Tesouro Selic | G8: Tesouro Selic Banco Beta | H8: CDI | I8: 1.0022 | K8: 45455 | L8: 46335 | M8: No vencimento | N8: Longo prazo | O8: 469289.69 | P8: 0 | Q8: 0 | R8: 0 | S8: 4468.06 | T8: 473757.75 | U8: 0 | V8: 0 | W8: 670.21 | X8: 0 | Y8: 473087.54 | Z8: 0.009521 | AA8: 1.0022 | AD8: 0.0095 | AG8: 0.003 | AH8: 22 | AI8: 647 | AJ8: Acima de 360 dias | AK8: N | AL8: 0.15 | AM8: N | AN8: N | AO8: AA | AP8: Banco Beta | AQ8: Custodiante Ficticio | AR8: CT-007 | AS8: No vencimento | AT8: 0 | AU8: Autorizado | AW8: Financeiro | AX8: 45688 | AY8: Ativa | AZ8: APL-007-202501 | BA8: =ROUND(T8-(O8+P8-Q8-R8+S8-IF(AK8="S",U8+V8,0)),2) -> 0 | BB8: =(O8+T8)/2 -> 471523.72
A9: 45688 | B9: APL-008 | C9: Recursos de Terceiros | D9: CC-009 | E9: Banco Beta | F9: Fundo DI | G9: Fundo DI Banco Beta | H9: CDI | I9: 0.951 | K9: 45517 | M9: Diaria | N9: Curto prazo | O9: 844492.7 | P9: 200638.22 | Q9: 0 | R9: 0 | S9: 8535.9 | T9: 1052386.4 | U9: 1280.38 | V9: 0 | W9: 0 | X9: 0 | Y9: 1052386.4 | Z9: 0.008167 | AA9: 0.8597 | AD9: 0.0095 | AG9: 0.003 | AH9: 22 | AJ9: Liquidez diaria | AK9: S | AL9: 0.15 | AM9: N | AN9: N | AO9: AA+ | AP9: Banco Beta | AQ9: Custodiante Ficticio | AR9: CT-008 | AS9: D+0 | AT9: 0 | AU9: Autorizado | AW9: Financeiro | AX9: 45688 | AY9: Ativa | AZ9: APL-008-202501 | BA9: =ROUND(T9-(O9+P9-Q9-R9+S9-IF(AK9="S",U9+V9,0)),2) -> 0 | BB9: =(O9+T9)/2 -> 948439.57
A10: 45688 | B10: APL-009 | C10: Recursos Proprios | D10: CC-004 | E10: Banco Beta | F10: CDB | G10: CDB Banco Beta | H10: CDI | I10: 1.0439 | K10: 45317 | L10: 46577 | M10: No vencimento | N10: Longo prazo | O10: 1439591.1 | P10: 0 | Q10: 0 | R10: 0 | S10: 14276.5 | T10: 1453867.6 | U10: 0 | V10: 0 | W10: 2141.47 | X10: 0 | Y10: 1451726.2 | Z10: 0.009917 | AA10: 1.0439 | AD10: 0.0095 | AG10: 0.003 | AH10: 22 | AI10: 889 | AJ10: Acima de 360 dias | AK10: N | AL10: 0.15 | AM10: N | AN10: S | AO10: AA | AP10: Banco Beta | AQ10: Custodiante Ficticio | AR10: CT-009 | AS10: No vencimento | AT10: 0 | AU10: Autorizado | AW10: Financeiro | AX10: 45688 | AY10: Ativa | AZ10: APL-009-202501 | BA10: =ROUND(T10-(O10+P10-Q10-R10+S10-IF(AK10="S",U10+V10,0)),2) -> 0 | BB10: =(O10+T10)/2 -> 1446729.4
A11: 45688 | B11: APL-010 | C11: Recursos Proprios | D11: CC-005 | E11: Banco Beta | F11: Tesouro Selic | G11: Tesouro Selic Banco Beta | H11: CDI | I11: 0.9928 | K11: 45612 | L11: 47072 | M11: No vencimento | N11: Longo prazo | O11: 1875223 | P11: 0 | Q11: 0 | R11: 0 | S11: 17686.35 | T11: 1892909.4 | U11: 0 | V11: 0 | W11: 2652.95 | X11: 0 | Y11: 1890256.4 | Z11: 0.009432 | AA11: 0.9928 | AD11: 0.0095 | AG11: 0.003 | AH11: 22 | AI11: 1384 | AJ11: Acima de 360 dias | AK11: N | AL11: 0.15 | AM11: N | AN11: N | AO11: AAA | AP11: Banco Beta | AQ11: Custodiante Ficticio | AR11: CT-010 | AS11: No vencimento | AT11: 0 | AU11: Autorizado | AW11: Financeiro | AX11: 45688 | AY11: Ativa | AZ11: APL-010-202501 | BA11: =ROUND(T11-(O11+P11-Q11-R11+S11-IF(AK11="S",U11+V11,0)),2) -> 0 | BB11: =(O11+T11)/2 -> 1884066.2
A12: 45688 | B12: APL-011 | C12: Recursos de Terceiros | D12: CC-006 | E12: Banco Epsilon | F12: Fundo Aplic. Automatica | G12: Fundo Aplic. Automatica Banco Epsilon | H12: CDI | I12: 0.2329 | K12: 45492 | M12: Diaria | N12: Curto prazo | O12: 2493967.1 | P12: 0 | Q12: 0 | R12: 0 | S12: 5518.03 | T12: 2498657.5 | U12: 827.7 | V12: 0 | W12: 0 | X12: 0 | Y12: 2498657.5 | Z12: 0.002213 | AA12: 0.2329 | AD12: 0.0095 | AG12: 0.003 | AH12: 22 | AJ12: Liquidez diaria | AK12: S | AL12: 0.15 | AM12: N | AN12: N | AO12: AA+ | AP12: Banco Epsilon | AQ12: Custodiante Ficticio | AR12: CT-011 | AS12: D+0 | AT12: 0 | AU12: Autorizado | AW12: Financeiro | AX12: 45688 | AY12: Ativa | AZ12: APL-011-202501 | BA12: =ROUND(T12-(O12+P12-Q12-R12+S12-IF(AK12="S",U12+V12,0)),2) -> 0 | BB12: =(O12+T12)/2 -> 2496312.3
A13: 45688 | B13: APL-012 | C13: Recursos Proprios | D13: CC-003 | E13: Banco Alfa | F13: Compromissada | G13: Compromissada Banco Alfa | H13: CDI | I13: 0.8627 | K13: 45319 | M13: Diaria | N13: Curto prazo | O13: 1990594.4 | P13: 0 | Q13: 0 | R13: 0 | S13: 16314.22 | T13: 2006908.7 | U13: 0 | V13: 0 | W13: 2447.13 | X13: 0 | Y13: 2004461.5 | Z13: 0.008196 | AA13: 0.8627 | AD13: 0.0095 | AG13: 0.003 | AH13: 22 | AJ13: Liquidez diaria | AK13: N | AL13: 0.15 | AM13: N | AN13: N | AO13: AAA | AP13: Banco Alfa | AQ13: Custodiante Ficticio | AR13: CT-012 | AS13: D+0 | AT13: 0 | AU13: Autorizado | AW13: Financeiro | AX13: 45688 | AY13: Ativa | AZ13: APL-012-202501 | BA13: =ROUND(T13-(O13+P13-Q13-R13+S13-IF(AK13="S",U13+V13,0)),2) -> 0 | BB13: =(O13+T13)/2 -> 1998751.5
A14: 45688 | B14: APL-013 | C14: Financiamento de Base | D14: CC-005 | E14: Banco Epsilon | F14: Tesouro IPCA+ | G14: Tesouro IPCA+ Banco Epsilon | H14: IPCA | J14: 0.0055 | K14: 45335 | L14: 47041 | M14: No vencimento | N14: Longo prazo | O14: 2158910.3 | P14: 0 | Q14: 0 | R14: 43178.21 | S14: 18350.74 | T14: 2134082.8 | U14: 0 | V14: 0 | W14: 2752.61 | X14: 0 | Y14: 2131330.2 | Z14: 0.0085 | AA14: 0.8947 | AD14: 0.0095 | AG14: 0.003 | AH14: 22 | AI14: 1353 | AJ14: Acima de 360 dias | AK14: N | AL14: 0.15 | AM14: N | AN14: N | AO14: AAA | AP14: Banco Epsilon | AQ14: Custodiante Ficticio | AR14: CT-013 | AS14: No vencimento | AT14: 0 | AU14: Autorizado | AW14: Financeiro | AX14: 45688 | AY14: Ativa | AZ14: APL-013-202501 | BA14: =ROUND(T14-(O14+P14-Q14-R14+S14-IF(AK14="S",U14+V14,0)),2) -> 0 | BB14: =(O14+T14)/2 -> 2146496.5
A15: 45688 | B15: APL-014 | C15: Recursos Proprios | D15: CC-005 | E15: Banco Alfa | F15: CDB | G15: CDB Banco Alfa | H15: CDI | I15: 1.0104 | K15: 45614 | L15: 46702 | M15: No vencimento | N15: Longo prazo | O15: 1161623.1 | P15: 71814.75 | Q15: 0 | R15: 0 | S15: 11494.86 | T15: 1244932.7 | U15: 0 | V15: 0 | W15: 1724.23 | X15: 0 | Y15: 1243208.5 | Z15: 0.009319 | AA15: 0.981 | AD15: 0.0095 | AG15: 0.003 | AH15: 22 | AI15: 1014 | AJ15: Acima de 360 dias | AK15: N | AL15: 0.15 | AM15: N | AN15: S | AO15: AA+ | AP15: Banco Alfa | AQ15: Custodiante Ficticio | AR15: CT-014 | AS15: No vencimento | AT15: 0 | AU15: Autorizado | AW15: Financeiro | AX15: 45688 | AY15: Ativa | AZ15: APL-014-202501 | BA15: =ROUND(T15-(O15+P15-Q15-R15+S15-IF(AK15="S",U15+V15,0)),2) -> 0 | BB15: =(O15+T15)/2 -> 1203277.9
A16: 45688 | B16: APL-015 | C16: Recursos Proprios | D16: CC-005 | E16: Banco Epsilon | F16: Fundo Aplic. Automatica | G16: Fundo Aplic. Automatica Banco Epsilon | H16: CDI | I16: 0.3263 | K16: 45368 | M16: Diaria | N16: Curto prazo | O16: 1293774.1 | P16: 0 | Q16: 0 | R16: 0 | S16: 4010.51 | T16: 1297183 | U16: 601.58 | V16: 0 | W16: 0 | X16: 0 | Y16: 1297183 | Z16: 0.0031 | AA16: 0.3263 | AD16: 0.0095 | AG16: 0.003 | AH16: 22 | AJ16: Liquidez diaria | AK16: S | AL16: 0.15 | AM16: N | AN16: N | AO16: AA+ | AP16: Banco Epsilon | AQ16: Custodiante Ficticio | AR16: CT-015 | AS16: D+0 | AT16: 0 | AU16: Autorizado | AW16: Financeiro | AX16: 45688 | AY16: Ativa | AZ16: APL-015-202501 | BA16: =ROUND(T16-(O16+P16-Q16-R16+S16-IF(AK16="S",U16+V16,0)),2) -> 0 | BB16: =(O16+T16)/2 -> 1295478.5
A17: 45688 | B17: APL-016 | C17: Recursos Proprios | D17: CC-009 | E17: Banco Beta | F17: Fundo DI | G17: Fundo DI Banco Beta | H17: CDI | I17: 0.9877 | K17: 45468 | M17: Diaria | N17: Curto prazo | O17: 2309963.5 | P17: 0 | Q17: 0 | R17: 0 | S17: 21674.73 | T17: 2328387 | U17: 3251.21 | V17: 0 | W17: 0 | X17: 0 | Y17: 2328387 | Z17: 0.009383 | AA17: 0.9877 | AD17: 0.0095 | AG17: 0.003 | AH17: 22 | AJ17: Liquidez diaria | AK17: S | AL17: 0.15 | AM17: N | AN17: N | AO17: AA | AP17: Banco Beta | AQ17: Custodiante Ficticio | AR17: CT-016 | AS17: D+0 | AT17: 0 | AU17: Autorizado | AW17: Financeiro | AX17: 45688 | AY17: Ativa | AZ17: APL-016-202501 | BA17: =ROUND(T17-(O17+P17-Q17-R17+S17-IF(AK17="S",U17+V17,0)),2) -> 0 | BB17: =(O17+T17)/2 -> 2319175.3
A18: 45688 | B18: APL-017 | C18: Recursos de Terceiros | D18: CC-004 | E18: Banco Epsilon | F18: CDB | G18: CDB Banco Epsilon | H18: CDI | I18: 0.9841 | K18: 45459 | L18: 45700 | M18: No vencimento | N18: Curto prazo | O18: 2201123.5 | P18: 0 | Q18: 0 | R18: 0 | S18: 20578.19 | T18: 2221701.7 | U18: 0 | V18: 0 | W18: 3086.73 | X18: 0 | Y18: 2218615 | Z18: 0.009349 | AA18: 0.9841 | AD18: 0.0095 | AG18: 0.003 | AH18: 22 | AI18: 12 | AJ18: Ate 90 dias | AK18: N | AL18: 0.15 | AM18: N | AN18: S | AO18: AA | AP18: Banco Epsilon | AQ18: Custodiante Ficticio | AR18: CT-017 | AS18: No vencimento | AT18: 0 | AU18: Autorizado | AW18: Financeiro | AX18: 45688 | AY18: Ativa | AZ18: APL-017-202501 | BA18: =ROUND(T18-(O18+P18-Q18-R18+S18-IF(AK18="S",U18+V18,0)),2) -> 0 | BB18: =(O18+T18)/2 -> 2211412.6
A19: 45688 | B19: APL-018 | C19: Recursos Proprios | D19: CC-003 | E19: Banco Alfa | F19: LCA | G19: LCA Banco Alfa | H19: CDI | I19: 0.9262 | K19: 45642 | L19: 45925 | M19: No vencimento | N19: Curto prazo | O19: 2369779.3 | P19: 0 | Q19: 0 | R19: 0 | S19: 20851.45 | T19: 2390630.7 | U19: 0 | V19: 0 | W19: 0 | X19: 0 | Y19: 2390630.7 | Z19: 0.008799 | AA19: 0.9262 | AD19: 0.0095 | AG19: 0.003 | AH19: 22 | AI19: 237 | AJ19: 91 a 360 dias | AK19: N | AL19: 0 | AM19: S | AN19: S | AO19: AA | AP19: Banco Alfa | AQ19: Custodiante Ficticio | AR19: CT-018 | AS19: No vencimento | AT19: 0 | AU19: Autorizado | AW19: Financeiro | AX19: 45688 | AY19: Ativa | AZ19: APL-018-202501 | BA19: =ROUND(T19-(O19+P19-Q19-R19+S19-IF(AK19="S",U19+V19,0)),2) -> 0 | BB19: =(O19+T19)/2 -> 2380205
A20: 45688 | B20: APL-019 | C20: Financiamento de Base | D20: CC-004 | E20: Banco Gama | F20: LCI | G20: LCI Banco Gama | H20: CDI | I20: 0.9199 | K20: 45563 | L20: 47306 | M20: No vencimento | N20: Longo prazo | O20: 1027531.1 | P20: 0 | Q20: 0 | R20: 0 | S20: 8979.65 | T20: 1036510.8 | U20: 0 | V20: 0 | W20: 0 | X20: 0 | Y20: 1036510.8 | Z20: 0.008739 | AA20: 0.9199 | AD20: 0.0095 | AG20: 0.003 | AH20: 22 | AI20: 1618 | AJ20: Acima de 360 dias | AK20: N | AL20: 0 | AM20: S | AN20: S | AO20: AAA | AP20: Banco Gama | AQ20: Custodiante Ficticio | AR20: CT-019 | AS20: No vencimento | AT20: 0 | AU20: Autorizado | AW20: Financeiro | AX20: 45688 | AY20: Ativa | AZ20: APL-019-202501 | BA20: =ROUND(T20-(O20+P20-Q20-R20+S20-IF(AK20="S",U20+V20,0)),2) -> 0 | BB20: =(O20+T20)/2 -> 1032021
A21: 45688 | B21: APL-020 | C21: Recursos Proprios | D21: CC-006 | E21: Cooperativa Delta | F21: Tesouro Selic | G21: Tesouro Selic Cooperativa Delta | H21: CDI | I21: 0.9904 | K21: 45550 | L21: 45755 | M21: No vencimento | N21: Curto prazo | O21: 1407107.7 | P21: 0 | Q21: 0 | R21: 0 | S21: 13239.2 | T21: 1420346.9 | U21: 0 | V21: 0 | W21: 1985.88 | X21: 0 | Y21: 1418361.1 | Z21: 0.009409 | AA21: 0.9904 | AD21: 0.0095 | AG21: 0.003 | AH21: 22 | AI21: 67 | AJ21: Ate 90 dias | AK21: N | AL21: 0.15 | AM21: N | AN21: N | AO21: AA | AP21: Cooperativa Delta | AQ21: Custodiante Ficticio | AR21: CT-020 | AS21: No vencimento | AT21: 0 | AU21: Autorizado | AW21: Financeiro | AX21: 45688 | AY21: Ativa | AZ21: APL-020-202501 | BA21: =ROUND(T21-(O21+P21-Q21-R21+S21-IF(AK21="S",U21+V21,0)),2) -> 0 | BB21: =(O21+T21)/2 -> 1413727.3
A22: 45688 | B22: APL-021 | C22: Financiamento de Base | D22: CC-001 | E22: Banco Alfa | F22: Fundo DI | G22: Fundo DI Banco Alfa | H22: CDI | I22: 0.9514 | K22: 45345 | M22: Diaria | N22: Curto prazo | O22: 2268279 | P22: 0 | Q22: 0 | R22: 0 | S22: 20501.39 | T22: 2285705.2 | U22: 3075.21 | V22: 0 | W22: 0 | X22: 0 | Y22: 2285705.2 | Z22: 0.009038 | AA22: 0.9514 | AD22: 0.0095 | AG22: 0.003 | AH22: 22 | AJ22: Liquidez diaria | AK22: S | AL22: 0.15 | AM22: N | AN22: N | AO22: AA | AP22: Banco Alfa | AQ22: Custodiante Ficticio | AR22: CT-021 | AS22: D+0 | AT22: 0 | AU22: Autorizado | AW22: Financeiro | AX22: 45688 | AY22: Ativa | AZ22: APL-021-202501 | BA22: =ROUND(T22-(O22+P22-Q22-R22+S22-IF(AK22="S",U22+V22,0)),2) -> 0 | BB22: =(O22+T22)/2 -> 2276992.1
A23: 45688 | B23: APL-022 | C23: Recursos Proprios | D23: CC-009 | E23: Banco Alfa | F23: Tesouro Selic | G23: Tesouro Selic Banco Alfa | H23: CDI | I23: 0.9926 | K23: 45543 | L23: 46707 | M23: No vencimento | N23: Longo prazo | O23: 2342009.9 | P23: 0 | Q23: 0 | R23: 0 | S23: 22084.45 | T23: 2364094.3 | U23: 0 | V23: 0 | W23: 3312.67 | X23: 0 | Y23: 2360781.7 | Z23: 0.00943 | AA23: 0.9926 | AD23: 0.0095 | AG23: 0.003 | AH23: 22 | AI23: 1019 | AJ23: Acima de 360 dias | AK23: N | AL23: 0.15 | AM23: N | AN23: N | AO23: AA | AP23: Banco Alfa | AQ23: Custodiante Ficticio | AR23: CT-022 | AS23: No vencimento | AT23: 0 | AU23: Autorizado | AW23: Financeiro | AX23: 45688 | AY23: Ativa | AZ23: APL-022-202501 | BA23: =ROUND(T23-(O23+P23-Q23-R23+S23-IF(AK23="S",U23+V23,0)),2) -> 0 | BB23: =(O23+T23)/2 -> 2353052.1
A24: 45688 | B24: APL-023 | C24: Recursos de Terceiros | D24: CC-004 | E24: Banco Beta | F24: Compromissada | G24: Compromissada Banco Beta | H24: CDI | I24: 0.8094 | K24: 45530 | M24: Diaria | N24: Curto prazo | O24: 1664507.7 | P24: 0 | Q24: 0 | R24: 0 | S24: 12798.9 | T24: 1677306.6 | U24: 0 | V24: 0 | W24: 1919.83 | X24: 0 | Y24: 1675386.8 | Z24: 0.007689 | AA24: 0.8094 | AD24: 0.0095 | AG24: 0.003 | AH24: 22 | AJ24: Liquidez diaria | AK24: N | AL24: 0.15 | AM24: N | AN24: N | AO24: AA+ | AP24: Banco Beta | AQ24: Custodiante Ficticio | AR24: CT-023 | AS24: D+0 | AT24: 0 | AU24: Autorizado | AW24: Financeiro | AX24: 45688 | AY24: Ativa | AZ24: APL-023-202501 | BA24: =ROUND(T24-(O24+P24-Q24-R24+S24-IF(AK24="S",U24+V24,0)),2) -> 0 | BB24: =(O24+T24)/2 -> 1670907.2
A25: 45688 | B25: APL-024 | C25: Financiamento de Base | D25: CC-002 | E25: Cooperativa Delta | F25: Tesouro Selic | G25: Tesouro Selic Cooperativa Delta | H25: CDI | I25: 0.9912 | K25: 45488 | L25: 45982 | M25: No vencimento | N25: Curto prazo | O25: 1834123.3 | P25: 0 | Q25: 0 | R25: 0 | S25: 17270.84 | T25: 1851394.1 | U25: 0 | V25: 0 | W25: 2590.63 | X25: 0 | Y25: 1848803.5 | Z25: 0.009416 | AA25: 0.9912 | AD25: 0.0095 | AG25: 0.003 | AH25: 22 | AI25: 294 | AJ25: 91 a 360 dias | AK25: N | AL25: 0.15 | AM25: N | AN25: N | AO25: AAA | AP25: Cooperativa Delta | AQ25: Custodiante Ficticio | AR25: CT-024 | AS25: No vencimento | AT25: 0 | AU25: Autorizado | AW25: Financeiro | AX25: 45688 | AY25: Ativa | AZ25: APL-024-202501 | BA25: =ROUND(T25-(O25+P25-Q25-R25+S25-IF(AK25="S",U25+V25,0)),2) -> 0 | BB25: =(O25+T25)/2 -> 1842758.7
A26: 45688 | B26: APL-025 | C26: Recursos de Terceiros | D26: CC-003 | E26: Banco Beta | F26: LCA | G26: LCA Banco Beta | H26: CDI | I26: 0.8995 | K26: 45389 | L26: 47335 | M26: No vencimento | N26: Longo prazo | O26: 662025.8 | P26: 132836.97 | Q26: 0 | R26: 0 | S26: 6224.74 | T26: 801087.51 | U26: 0 | V26: 0 | W26: 0 | X26: 0 | Y26: 801087.51 | Z26: 0.007831 | AA26: 0.8243 | AD26: 0.0095 | AG26: 0.003 | AH26: 22 | AI26: 1647 | AJ26: Acima de 360 dias | AK26: N | AL26: 0 | AM26: S | AN26: S | AO26: AAA | AP26: Banco Beta | AQ26: Custodiante Ficticio | AR26: CT-025 | AS26: No vencimento | AT26: 0 | AU26: Autorizado | AW26: Financeiro | AX26: 45688 | AY26: Ativa | AZ26: APL-025-202501 | BA26: =ROUND(T26-(O26+P26-Q26-R26+S26-IF(AK26="S",U26+V26,0)),2) -> 0 | BB26: =(O26+T26)/2 -> 731556.66
A27: 45688 | B27: APL-026 | C27: Recursos Proprios | D27: CC-002 | E27: Cooperativa Delta | F27: LCA | G27: LCA Cooperativa Delta | H27: CDI | I27: 0.9448 | K27: 45539 | L27: 45979 | M27: No vencimento | N27: Curto prazo | O27: 2129304.5 | P27: 0 | Q27: 392121.2 | R27: 0 | S27: 17352.02 | T27: 1754535.4 | U27: 0 | V27: 0 | W27: 0 | X27: 0 | Y27: 1754535.4 | Z27: 0.008149 | AA27: 0.8578 | AD27: 0.0095 | AG27: 0.003 | AH27: 22 | AI27: 291 | AJ27: 91 a 360 dias | AK27: N | AL27: 0 | AM27: S | AN27: S | AO27: AAA | AP27: Cooperativa Delta | AQ27: Custodiante Ficticio | AR27: CT-026 | AS27: No vencimento | AT27: 0 | AU27: Autorizado | AW27: Financeiro | AX27: 45688 | AY27: Ativa | AZ27: APL-026-202501 | BA27: =ROUND(T27-(O27+P27-Q27-R27+S27-IF(AK27="S",U27+V27,0)),2) -> 0 | BB27: =(O27+T27)/2 -> 1941920
A28: 45688 | B28: APL-027 | C28: Recursos Proprios | D28: CC-007 | E28: Cooperativa Delta | F28: LCI | G28: LCI Cooperativa Delta | H28: CDI | I28: 0.8702 | K28: 45520 | L28: 46205 | M28: No vencimento | N28: Longo prazo | O28: 1006533.3 | P28: 0 | Q28: 0 | R28: 0 | S28: 8320.91 | T28: 1014854.2 | U28: 0 | V28: 0 | W28: 0 | X28: 0 | Y28: 1014854.2 | Z28: 0.008267 | AA28: 0.8702 | AD28: 0.0095 | AG28: 0.003 | AH28: 22 | AI28: 517 | AJ28: Acima de 360 dias | AK28: N | AL28: 0 | AM28: S | AN28: S | AO28: AA+ | AP28: Cooperativa Delta | AQ28: Custodiante Ficticio | AR28: CT-027 | AS28: No vencimento | AT28: 0 | AU28: Autorizado | AW28: Financeiro | AX28: 45688 | AY28: Ativa | AZ28: APL-027-202501 | BA28: =ROUND(T28-(O28+P28-Q28-R28+S28-IF(AK28="S",U28+V28,0)),2) -> 0 | BB28: =(O28+T28)/2 -> 1010693.8
A29: 45688 | B29: APL-028 | C29: Financiamento de Base | D29: CC-009 | E29: Banco Gama | F29: Compromissada | G29: Compromissada Banco Gama | H29: CDI | I29: 0.8662 | K29: 45496 | M29: Diaria | N29: Curto prazo | O29: 1242345 | P29: 0 | Q29: 378569.87 | R29: 0 | S29: 8665.53 | T29: 872440.62 | U29: 0 | V29: 0 | W29: 1299.83 | X29: 0 | Y29: 871140.79 | Z29: 0.006975 | AA29: 0.7342 | AD29: 0.0095 | AG29: 0.003 | AH29: 22 | AJ29: Liquidez diaria | AK29: N | AL29: 0.15 | AM29: N | AN29: N | AO29: AA | AP29: Banco Gama | AQ29: Custodiante Ficticio | AR29: CT-028 | AS29: D+0 | AT29: 0 | AU29: Autorizado | AW29: Financeiro | AX29: 45688 | AY29: Ativa | AZ29: APL-028-202501 | BA29: =ROUND(T29-(O29+P29-Q29-R29+S29-IF(AK29="S",U29+V29,0)),2) -> 0 | BB29: =(O29+T29)/2 -> 1057392.8
A30: 45716 | B30: APL-001 | C30: Financiamento de Base | D30: CC-002 | E30: Banco Alfa | F30: LCA | G30: LCA Banco Alfa | H30: CDI | I30: 0.9274 | K30: 45635 | L30: 46117 | M30: No vencimento | N30: Longo prazo | O30: 2255538.4 | P30: 0 | Q30: 0 | R30: 0 | S30: 18407.72 | T30: 2273946.1 | U30: 0 | V30: 0 | W30: 0 | X30: 0 | Y30: 2273946.1 | Z30: 0.008161 | AA30: 0.9274 | AD30: 0.0088 | AG30: 0.0045 | AH30: 18 | AI30: 401 | AJ30: Acima de 360 dias | AK30: N | AL30: 0 | AM30: S | AN30: S | AO30: AA+ | AP30: Banco Alfa | AQ30: Custodiante Ficticio | AR30: CT-001 | AS30: No vencimento | AT30: 0 | AU30: Autorizado | AW30: Financeiro | AX30: 45716 | AY30: Ativa | AZ30: APL-001-202502 | BA30: =ROUND(T30-(O30+P30-Q30-R30+S30-IF(AK30="S",U30+V30,0)),2) -> 0 | BB30: =(O30+T30)/2 -> 2264742.2
A31: 45716 | B31: APL-002 | C31: Recursos Proprios | D31: CC-009 | E31: Banco Epsilon | F31: LCA | G31: LCA Banco Epsilon | H31: CDI | I31: 0.9221 | K31: 45475 | L31: 45695 | M31: No vencimento | N31: Curto prazo | O31: 1437533.8 | P31: 0 | Q31: 59703.75 | R31: 0 | S31: 11422.61 | T31: 1389252.6 | U31: 0 | V31: 0 | W31: 0 | X31: 0 | Y31: 1389252.6 | Z31: 0.007946 | AA31: 0.903 | AD31: 0.0088 | AG31: 0.0045 | AH31: 18 | AI31: -21 | AJ31: Ate 90 dias | AK31: N | AL31: 0 | AM31: S | AN31: S | AO31: AA+ | AP31: Banco Epsilon | AQ31: Custodiante Ficticio | AR31: CT-002 | AS31: No vencimento | AT31: 0 | AU31: Autorizado | AW31: Financeiro | AX31: 45716 | AY31: Ativa | AZ31: APL-002-202502 | BA31: =ROUND(T31-(O31+P31-Q31-R31+S31-IF(AK31="S",U31+V31,0)),2) -> 0 | BB31: =(O31+T31)/2 -> 1413393.2
A32: 45716 | B32: APL-003 | C32: Recursos Proprios | D32: CC-007 | E32: Banco Beta | F32: Tesouro IPCA+ | G32: Tesouro IPCA+ Banco Beta | H32: IPCA | J32: 0.0048 | K32: 45523 | L32: 46412 | M32: No vencimento | N32: Longo prazo | O32: 228955.77 | P32: 0 | Q32: 0 | R32: 0 | S32: 2129.29 | T32: 231085.06 | U32: 0 | V32: 0 | W32: 319.39 | X32: 0 | Y32: 230765.67 | Z32: 0.0093 | AA32: 1.0568 | AD32: 0.0088 | AG32: 0.0045 | AH32: 18 | AI32: 696 | AJ32: Acima de 360 dias | AK32: N | AL32: 0.15 | AM32: N | AN32: N | AO32: AAA | AP32: Banco Beta | AQ32: Custodiante Ficticio | AR32: CT-003 | AS32: No vencimento | AT32: 0 | AU32: Autorizado | AW32: Financeiro | AX32: 45716 | AY32: Ativa | AZ32: APL-003-202502 | BA32: =ROUND(T32-(O32+P32-Q32-R32+S32-IF(AK32="S",U32+V32,0)),2) -> 0 | BB32: =(O32+T32)/2 -> 230020.41
A33: 45716 | B33: APL-004 | C33: Recursos de Terceiros | D33: CC-005 | E33: Banco Alfa | F33: Tesouro Selic | G33: Tesouro Selic Banco Alfa | H33: CDI | I33: 1.0061 | K33: 45335 | L33: 45836 | M33: No vencimento | N33: Curto prazo | O33: 1855408.9 | P33: 0 | Q33: 0 | R33: 0 | S33: 16427.2 | T33: 1871836.1 | U33: 0 | V33: 0 | W33: 2464.08 | X33: 0 | Y33: 1869372 | Z33: 0.008854 | AA33: 1.0061 | AD33: 0.0088 | AG33: 0.0045 | AH33: 18 | AI33: 120 | AJ33: 91 a 360 dias | AK33: N | AL33: 0.15 | AM33: N | AN33: N | AO33: AAA | AP33: Banco Alfa | AQ33: Custodiante Ficticio | AR33: CT-004 | AS33: No vencimento | AT33: 0 | AU33: Autorizado | AW33: Financeiro | AX33: 45716 | AY33: Ativa | AZ33: APL-004-202502 | BA33: =ROUND(T33-(O33+P33-Q33-R33+S33-IF(AK33="S",U33+V33,0)),2) -> 0 | BB33: =(O33+T33)/2 -> 1863622.5
A34: 45716 | B34: APL-005 | C34: Recursos de Terceiros | D34: CC-004 | E34: Cooperativa Delta | F34: LCA | G34: LCA Cooperativa Delta | H34: CDI | I34: 0.9293 | K34: 45340 | L34: 46711 | M34: No vencimento | N34: Longo prazo | O34: 127036.44 | P34: 0 | Q34: 0 | R34: 0 | S34: 1038.88 | T34: 128075.32 | U34: 0 | V34: 0 | W34: 0 | X34: 0 | Y34: 128075.32 | Z34: 0.008178 | AA34: 0.9293 | AD34: 0.0088 | AG34: 0.0045 | AH34: 18 | AI34: 995 | AJ34: Acima de 360 dias | AK34: N | AL34: 0 | AM34: S | AN34: S | AO34: AA | AP34: Cooperativa Delta | AQ34: Custodiante Ficticio | AR34: CT-005 | AS34: No vencimento | AT34: 0 | AU34: Autorizado | AW34: Financeiro | AX34: 45716 | AY34: Ativa | AZ34: APL-005-202502 | BA34: =ROUND(T34-(O34+P34-Q34-R34+S34-IF(AK34="S",U34+V34,0)),2) -> 0 | BB34: =(O34+T34)/2 -> 127555.88
A35: 45716 | B35: APL-006 | C35: Recursos Proprios | D35: CC-002 | E35: Banco Gama | F35: Fundo DI | G35: Fundo DI Banco Gama | H35: CDI | I35: 0.959 | K35: 45350 | M35: Diaria | N35: Curto prazo | O35: 1169844.8 | P35: 0 | Q35: 0 | R35: 0 | S35: 9872.55 | T35: 1178236.5 | U35: 1480.88 | V35: 0 | W35: 0 | X35: 0 | Y35: 1178236.5 | Z35: 0.008439 | AA35: 0.959 | AD35: 0.0088 | AG35: 0.0045 | AH35: 18 | AJ35: Liquidez diaria | AK35: S | AL35: 0.15 | AM35: N | AN35: N | AO35: AA | AP35: Banco Gama | AQ35: Custodiante Ficticio | AR35: CT-006 | AS35: D+0 | AT35: 0 | AU35: Autorizado | AW35: Financeiro | AX35: 45716 | AY35: Ativa | AZ35: APL-006-202502 | BA35: =ROUND(T35-(O35+P35-Q35-R35+S35-IF(AK35="S",U35+V35,0)),2) -> 0 | BB35: =(O35+T35)/2 -> 1174040.6
A36: 45716 | B36: APL-007 | C36: Financiamento de Base | D36: CC-002 | E36: Banco Beta | F36: Tesouro Selic | G36: Tesouro Selic Banco Beta | H36: CDI | I36: 1.0022 | K36: 45455 | L36: 46335 | M36: No vencimento | N36: Longo prazo | O36: 473757.75 | P36: 0 | Q36: 0 | R36: 0 | S36: 4178.24 | T36: 477935.99 | U36: 0 | V36: 0 | W36: 626.74 | X36: 0 | Y36: 477309.25 | Z36: 0.008819 | AA36: 1.0022 | AD36: 0.0088 | AG36: 0.0045 | AH36: 18 | AI36: 619 | AJ36: Acima de 360 dias | AK36: N | AL36: 0.15 | AM36: N | AN36: N | AO36: AAA | AP36: Banco Beta | AQ36: Custodiante Ficticio | AR36: CT-007 | AS36: No vencimento | AT36: 0 | AU36: Autorizado | AW36: Financeiro | AX36: 45716 | AY36: Ativa | AZ36: APL-007-202502 | BA36: =ROUND(T36-(O36+P36-Q36-R36+S36-IF(AK36="S",U36+V36,0)),2) -> 0 | BB36: =(O36+T36)/2 -> 475846.87
A37: 45716 | B37: APL-008 | C37: Recursos de Terceiros | D37: CC-009 | E37: Banco Beta | F37: Fundo DI | G37: Fundo DI Banco Beta | H37: CDI | I37: 0.951 | K37: 45517 | M37: Diaria | N37: Curto prazo | O37: 1052386.4 | P37: 0 | Q37: 0 | R37: 0 | S37: 8807.21 | T37: 1059872.6 | U37: 1321.08 | V37: 0 | W37: 0 | X37: 0 | Y37: 1059872.6 | Z37: 0.008369 | AA37: 0.951 | AD37: 0.0088 | AG37: 0.0045 | AH37: 18 | AJ37: Liquidez diaria | AK37: S | AL37: 0.15 | AM37: N | AN37: N | AO37: AAA | AP37: Banco Beta | AQ37: Custodiante Ficticio | AR37: CT-008 | AS37: D+0 | AT37: 0 | AU37: Autorizado | AW37: Financeiro | AX37: 45716 | AY37: Ativa | AZ37: APL-008-202502 | BA37: =ROUND(T37-(O37+P37-Q37-R37+S37-IF(AK37="S",U37+V37,0)),2) -> 0 | BB37: =(O37+T37)/2 -> 1056129.5
A38: 45716 | B38: APL-009 | C38: Recursos Proprios | D38: CC-004 | E38: Banco Beta | F38: CDB | G38: CDB Banco Beta | H38: CDI | I38: 1.0439 | K38: 45317 | L38: 46577 | M38: No vencimento | N38: Longo prazo | O38: 1453867.6 | P38: 0 | Q38: 297260.14 | R38: 0 | S38: 11990.33 | T38: 1168597.8 | U38: 0 | V38: 0 | W38: 1798.55 | X38: 0 | Y38: 1166799.3 | Z38: 0.008247 | AA38: 0.9372 | AD38: 0.0088 | AG38: 0.0045 | AH38: 18 | AI38: 861 | AJ38: Acima de 360 dias | AK38: N | AL38: 0.15 | AM38: N | AN38: S | AO38: AA+ | AP38: Banco Beta | AQ38: Custodiante Ficticio | AR38: CT-009 | AS38: No vencimento | AT38: 0 | AU38: Autorizado | AW38: Financeiro | AX38: 45716 | AY38: Ativa | AZ38: APL-009-202502 | BA38: =ROUND(T38-(O38+P38-Q38-R38+S38-IF(AK38="S",U38+V38,0)),2) -> 0 | BB38: =(O38+T38)/2 -> 1311232.7
A39: 45716 | B39: APL-010 | C39: Recursos Proprios | D39: CC-005 | E39: Banco Beta | F39: Tesouro Selic | G39: Tesouro Selic Banco Beta | H39: CDI | I39: 0.9928 | K39: 45612 | L39: 47072 | M39: No vencimento | N39: Longo prazo | O39: 1892909.4 | P39: 0 | Q39: 0 | R39: 0 | S39: 16537.67 | T39: 1909447 | U39: 0 | V39: 0 | W39: 2480.65 | X39: 0 | Y39: 1906966.4 | Z39: 0.008737 | AA39: 0.9928 | AD39: 0.0088 | AG39: 0.0045 | AH39: 18 | AI39: 1356 | AJ39: Acima de 360 dias | AK39: N | AL39: 0.15 | AM39: N | AN39: N | AO39: AA | AP39: Banco Beta | AQ39: Custodiante Ficticio | AR39: CT-010 | AS39: No vencimento | AT39: 0 | AU39: Autorizado | AW39: Financeiro | AX39: 45716 | AY39: Ativa | AZ39: APL-010-202502 | BA39: =ROUND(T39-(O39+P39-Q39-R39+S39-IF(AK39="S",U39+V39,0)),2) -> 0 | BB39: =(O39+T39)/2 -> 1901178.2
A40: 45716 | B40: APL-011 | C40: Recursos de Terceiros | D40: CC-006 | E40: Banco Epsilon | F40: Fundo Aplic. Automatica | G40: Fundo Aplic. Automatica Banco Epsilon | H40: CDI | I40: 0.2329 | K40: 45492 | M40: Diaria | N40: Curto prazo | O40: 2498657.5 | P40: 0 | Q40: 0 | R40: 0 | S40: 5121.05 | T40: 2503010.4 | U40: 768.16 | V40: 0 | W40: 0 | X40: 0 | Y40: 2503010.4 | Z40: 0.00205 | AA40: 0.2329 | AD40: 0.0088 | AG40: 0.0045 | AH40: 18 | AJ40: Liquidez diaria | AK40: S | AL40: 0.15 | AM40: N | AN40: N | AO40: AA+ | AP40: Banco Epsilon | AQ40: Custodiante Ficticio | AR40: CT-011 | AS40: D+0 | AT40: 0 | AU40: Autorizado | AW40: Financeiro | AX40: 45716 | AY40: Ativa | AZ40: APL-011-202502 | BA40: =ROUND(T40-(O40+P40-Q40-R40+S40-IF(AK40="S",U40+V40,0)),2) -> 0 | BB40: =(O40+T40)/2 -> 2500833.9
...

Sheet Config
A1: Parâmetros do relatório
A3: Mês de referência | B3: 45747 | C3: Atualizado pela macro ao importar. Pode ser alterado para rever meses anteriores.
A4: Limite de concentração por instituição | B4: 0.3 | C4: Parâmetro FICTÍCIO. Substitua pelo limite da sua política.
A5: Meta de rentabilidade (% do CDI) | B5: 1 | C5: Parâmetro FICTÍCIO.
A6: Tolerância de continuidade do saldo (R$) | B6: 1 | C6: Diferença aceitável entre saldo final anterior e saldo inicial atual.
A7: Pasta do PDF (vazio = pasta deste arquivo) | C7: Caminho local. Se o arquivo estiver em nuvem, a macro pergunta a pasta.
A8: Status do relatório | B8: FINAL | C8: Preenchido pela macro (FINAL ou PRELIMINAR). Não editar.
A9: Mês anterior (calculado) | B9: =EOMONTH(B3,-1) -> 45716

Sheet Cadastros
A1: Instituicao | C1: Modalidade | E1: Fonte | G1: Mes | I1: Novas instituições ou modalidades: acrescente uma linha na tabela correspondente (a conferência acusa ERRO até lá).
A2: Banco Alfa | C2: CDB | E2: Recursos Proprios | G2: 45688
A3: Banco Beta | C3: LCA | E3: Recursos de Terceiros | G3: 45716
A4: Banco Gama | C4: LCI | E4: Financiamento de Base | G4: 45747
A5: Cooperativa Delta | C5: Fundo DI
A6: Banco Epsilon | C6: Fundo Aplic. Automatica
C7: Tesouro Selic
C8: Tesouro IPCA+
C9: Compromissada

Sheet Indicadores
A1: Mes | B1: CDI_Mes | C1: IPCA_Mes | D1: Data_Base_Original | F1: Valores FICTÍCIOS, gravados pela macro a partir das colunas CDI_Mes e IPCA_Mes da planilha mensal.
A2: 45688 | B2: 0.0095 | C2: 0.003 | D2: 45688
A3: 45716 | B3: 0.0088 | C3: 0.0045 | D3: 45716
A4: 45747 | B4: 0.0097 | C4: -0.001 | D4: 45747

Sheet Log
A1: Data_Hora | B1: Usuario | C1: Arquivo | D1: Mes_Ref | E1: Linhas | F1: Data_Base_Original | G1: Observacao
B2: script | C2: construir_base.py | D2: 45747 | E2: 84 | G2: Carga inicial de exemplo (jan-mar/2025, dados fictícios)
